<robot
  name="IRIS_V_URDF_2">
  <link
    name="base_link">
    <inertial>
      <origin
        xyz="0.03046 -4.3725E-05 0.23809"
        rpy="0 0 0" />
      <mass
        value="50" />
      <inertia
        ixx="5.53"
        ixy="0.0015246"
        ixz="-2.2693"
        iyy="14.276"
        iyz="0.00077818"
        izz="12.758" />
    </inertial>
    <visual>
      <origin
        xyz="0 0 0"
        rpy="0 0 0" />
      <geometry>
        <mesh
          filename="package://IRIS_V_URDF_2/meshes/base_link.STL" />
      </geometry>
      <material
        name="">
        <color
          rgba="1 1 1 0.5" />
      </material>
    </visual>
    <collision>
      <origin
        xyz="0 0 0"
        rpy="0 0 0" />
      <geometry>
        <mesh
          filename="package://IRIS_V_URDF_2/meshes/base_link.STL" />
      </geometry>
    </collision>
  </link>
  <link
    name="kinect_link">
    <inertial>
      <origin
        xyz="0.00014306 0.012039 0.0012775"
        rpy="0 0 0" />
      <mass
        value="0.64646" />
      <inertia
        ixx="0.00042407"
        ixy="1.2668E-06"
        ixz="2.5259E-06"
        iyy="0.0029629"
        iyz="-5.3748E-06"
        izz="0.0030028" />
    </inertial>
    <visual>
      <origin
        xyz="0 0 0"
        rpy="0 0 0" />
      <geometry>
        <mesh
          filename="package://IRIS_V_URDF_2/meshes/kinect_link.STL" />
      </geometry>
      <material
        name="">
        <color
          rgba="0.79216 0.81961 0.93333 1" />
      </material>
    </visual>
    <collision>
      <origin
        xyz="0 0 0"
        rpy="0 0 0" />
      <geometry>
        <mesh
          filename="package://IRIS_V_URDF_2/meshes/kinect_link.STL" />
      </geometry>
    </collision>
  </link>
  <joint
    name="kinect_joint"
    type="fixed">
    <origin
      xyz="0.67234 0.0001384 0.4551"
      rpy="2.0944 1.444E-16 1.5708" />
    <parent
      link="base_link" />
    <child
      link="kinect_link" />
    <axis
      xyz="0 0 0" />
  </joint>
  <link
    name="FL_Wheel">
    <inertial>
      <origin
        xyz="-1.1102E-15 -0.026 1.1102E-15"
        rpy="0 0 0" />
      <mass
        value="2.2106" />
      <inertia
        ixx="0.0080212"
        ixy="6.4792E-19"
        ixz="-6.5052E-19"
        iyy="0.015046"
        iyz="4.8471E-19"
        izz="0.0080212" />
    </inertial>
    <visual>
      <origin
        xyz="0 0 0"
        rpy="0 0 0" />
      <geometry>
        <mesh
          filename="package://IRIS_V_URDF_2/meshes/FL_Wheel.STL" />
      </geometry>
      <material
        name="">
        <color
          rgba="0.79216 0.81961 0.93333 1" />
      </material>
    </visual>
    <collision>
      <origin
        xyz="0 0 0"
        rpy="0 0 0" />
      <geometry>
        <mesh
          filename="package://IRIS_V_URDF_2/meshes/FL_Wheel.STL" />
      </geometry>
    </collision>
  </link>
  <joint
    name="FL_joint"
    type="continuous">
    <origin
      xyz="0.36017 0.27899 0"
      rpy="9.147E-17 0.23805 3.1416" />
    <parent
      link="base_link" />
    <child
      link="FL_Wheel" />
    <axis
      xyz="0 -1 0" />
    <limit
      effort="0"
      velocity="4.3" />
  </joint>
  <link
    name="fr_wheel">
    <inertial>
      <origin
        xyz="-9.992E-16 -0.026 1.1102E-15"
        rpy="0 0 0" />
      <mass
        value="2.2106" />
      <inertia
        ixx="0.0080212"
        ixy="8.8397E-19"
        ixz="-3.2526E-19"
        iyy="0.015046"
        iyz="4.6848E-19"
        izz="0.0080212" />
    </inertial>
    <visual>
      <origin
        xyz="0 0 0"
        rpy="0 0 0" />
      <geometry>
        <mesh
          filename="package://IRIS_V_URDF_2/meshes/fr_wheel.STL" />
      </geometry>
      <material
        name="">
        <color
          rgba="0.79216 0.81961 0.93333 1" />
      </material>
    </visual>
    <collision>
      <origin
        xyz="0 0 0"
        rpy="0 0 0" />
      <geometry>
        <mesh
          filename="package://IRIS_V_URDF_2/meshes/fr_wheel.STL" />
      </geometry>
    </collision>
  </link>
  <joint
    name="fr_joint"
    type="continuous">
    <origin
      xyz="0.36017 -0.279 0"
      rpy="-3.1416 -1.417 3.1416" />
    <parent
      link="base_link" />
    <child
      link="fr_wheel" />
    <axis
      xyz="0 -1 0" />
    <limit
      effort="0"
      velocity="4.3" />
  </joint>
  <link
    name="bl_wheel">
    <inertial>
      <origin
        xyz="-8.8818E-16 -0.026 8.8818E-16"
        rpy="0 0 0" />
      <mass
        value="2.2106" />
      <inertia
        ixx="0.0080212"
        ixy="-1.7096E-19"
        ixz="4.3368E-19"
        iyy="0.015046"
        iyz="1.4843E-20"
        izz="0.0080212" />
    </inertial>
    <visual>
      <origin
        xyz="0 0 0"
        rpy="0 0 0" />
      <geometry>
        <mesh
          filename="package://IRIS_V_URDF_2/meshes/bl_wheel.STL" />
      </geometry>
      <material
        name="">
        <color
          rgba="0.79216 0.81961 0.93333 1" />
      </material>
    </visual>
    <collision>
      <origin
        xyz="0 0 0"
        rpy="0 0 0" />
      <geometry>
        <mesh
          filename="package://IRIS_V_URDF_2/meshes/bl_wheel.STL" />
      </geometry>
    </collision>
  </link>
  <joint
    name="bl_link"
    type="continuous">
    <origin
      xyz="-0.36055 0.331 0"
      rpy="-3.1416 -1.179 3.1416" />
    <parent
      link="base_link" />
    <child
      link="bl_wheel" />
    <axis
      xyz="0 -1 0" />
    <limit
      effort="0"
      velocity="4.3" />
  </joint>
  <link
    name="br_wheel">
    <inertial>
      <origin
        xyz="-1.1102E-15 -0.026 1.1657E-15"
        rpy="0 0 0" />
      <mass
        value="2.2106" />
      <inertia
        ixx="0.0080212"
        ixy="-4.8146E-20"
        ixz="3.1296E-33"
        iyy="0.015046"
        iyz="-8.8139E-21"
        izz="0.0080212" />
    </inertial>
    <visual>
      <origin
        xyz="0 0 0"
        rpy="0 0 0" />
      <geometry>
        <mesh
          filename="package://IRIS_V_URDF_2/meshes/br_wheel.STL" />
      </geometry>
      <material
        name="">
        <color
          rgba="0.79216 0.81961 0.93333 1" />
      </material>
    </visual>
    <collision>
      <origin
        xyz="0 0 0"
        rpy="0 0 0" />
      <geometry>
        <mesh
          filename="package://IRIS_V_URDF_2/meshes/br_wheel.STL" />
      </geometry>
    </collision>
  </link>
  <joint
    name="br_joint"
    type="continuous">
    <origin
      xyz="-0.36055 -0.33101 0"
      rpy="1.7389E-16 -2.949E-17 -3.1416" />
    <parent
      link="base_link" />
    <child
      link="br_wheel" />
    <axis
      xyz="0 -1 0" />
    <limit
      effort="0"
      velocity="4.3" />
  </joint>
</robot>